Workbook

Sheet Data
A1: Region | B1: Product | C1: Units | D1: Price
A2: North | B2: A | C2: 10 | D2: 1.5
A3: South | B3: B | C3: 20 | D3: 2.25
A4: North | B4: A | C4: 30 | D4: 1.5
A5: South | B5: C | C5: 40 | D5: 3
A6: North | B6: B | C6: 50 | D6: 2.25
A7: South | B7: A | C7: 60 | D7: 1.5
A8: North | B8: C | C8: 70 | D8: 3
A9: South | B9: B | C9: 80 | D9: 2.25
A10: North | B10: A | C10: 90 | D10: 1.5
A11: South | B11: C | C11: 100 | D11: 3
A12: North | C12: 110 | D12: 1.5
A13: South | B13: B | C13: #N/A | D13: 2.25

Sheet G
A1: GROUPBY(Data!A2:A13,Data!C2:C13,SUM) | B1: {=_xlfn.GROUPBY(Data!A2:A13,Data!C2:C13,_xleta.SUM)} -> North | C1: 360
B2: South | C2: #N/A
B3: Total | C3: #N/A
A26: GROUPBY(Data!A1:A13,Data!C1:C13,SUM,0) | B26: {=_xlfn.GROUPBY(Data!A1:A13,Data!C1:C13,_xleta.SUM,0)} -> North | C26: 360
B27: Region | C27: 0
B28: South | C28: #N/A
B29: Total | C29: #N/A
A51: GROUPBY(Data!A1:A13,Data!C1:C13,SUM,1) | B51: {=_xlfn.GROUPBY(Data!A1:A13,Data!C1:C13,_xleta.SUM,1)} -> North | C51: 360
B52: South | C52: #N/A
B53: Total | C53: #N/A
A76: GROUPBY(Data!A1:A13,Data!C1:C13,SUM,2) | B76: {=_xlfn.GROUPBY(Data!A1:A13,Data!C1:C13,_xleta.SUM,2)} -> Row Field 1 | C76: Value 1
B77: North | C77: 360
B78: Region | C78: 0
B79: South | C79: #N/A
B80: Total | C80: #N/A
A101: GROUPBY(Data!A1:A13,Data!C1:C13,SUM,3) | B101: {=_xlfn.GROUPBY(Data!A1:A13,Data!C1:C13,_xleta.SUM,3)} -> Region | C101: Units
B102: North | C102: 360
B103: South | C103: #N/A
B104: Total | C104: #N/A
A126: GROUPBY(Data!A1:A13,Data!C1:C13,SUM) | B126: {=_xlfn.GROUPBY(Data!A1:A13,Data!C1:C13,_xleta.SUM)} -> North | C126: 360
B127: South | C127: #N/A
B128: Total | C128: #N/A
A151: GROUPBY(Data!A2:B13,Data!C2:C13,SUM,0,-2) | B151: {=_xlfn.GROUPBY(Data!A2:B13,Data!C2:C13,_xleta.SUM,0,-2)} -> Grand Total | D151: #N/A
B152: North | D152: 360
B153: North | C153: A | D153: 130
B154: North | C154: B | D154: 50
B155: North | C155: C | D155: 70
B156: North | C156: 0 | D156: 110
B157: South | D157: #N/A
B158: South | C158: A | D158: 60
B159: South | C159: B | D159: #N/A
B160: South | C160: C | D160: 140
A176: GROUPBY(Data!A2:B13,Data!C2:C13,SUM,0,-1) | B176: {=_xlfn.GROUPBY(Data!A2:B13,Data!C2:C13,_xleta.SUM,0,-1)} -> Total | D176: #N/A
B177: North | C177: A | D177: 130
B178: North | C178: B | D178: 50
B179: North | C179: C | D179: 70
B180: North | C180: 0 | D180: 110
B181: South | C181: A | D181: 60
B182: South | C182: B | D182: #N/A
B183: South | C183: C | D183: 140
...

Sheet P
A1: PIVOTBY(Data!A2:A13,Data!B2:B13,Data!C2:C13,SUM) | B1: {=_xlfn.PIVOTBY(Data!A2:A13,Data!B2:B13,Data!C2:C13,_xleta.SUM)} | C1: A | D1: B | E1: C | F1: 0 | G1: Total
B2: North | C2: 130 | D2: 50 | E2: 70 | F2: 110 | G2: 360
B3: South | C3: 60 | D3: #N/A | E3: 140 | G3: #N/A
B4: Total | C4: 190 | D4: #N/A | E4: 210 | F4: 110 | G4: #N/A
A26: PIVOTBY(Data!A1:A13,Data!B1:B13,Data!C1:C13,SUM,0) | B26: {=_xlfn.PIVOTBY(Data!A1:A13,Data!B1:B13,Data!C1:C13,_xleta.SUM,0)} | C26: A | D26: B | E26: C | F26: Product | G26: 0 | H26: Total
B27: North | C27: 130 | D27: 50 | E27: 70 | G27: 110 | H27: 360
B28: Region | F28: 0 | H28: 0
B29: South | C29: 60 | D29: #N/A | E29: 140 | H29: #N/A
B30: Total | C30: 190 | D30: #N/A | E30: 210 | F30: 0 | G30: 110 | H30: #N/A
A51: PIVOTBY(Data!A1:A13,Data!B1:B13,Data!C1:C13,SUM,1) | B51: {=_xlfn.PIVOTBY(Data!A1:A13,Data!B1:B13,Data!C1:C13,_xleta.SUM,1)} | C51: A | D51: B | E51: C | F51: 0 | G51: Total
B52: North | C52: 130 | D52: 50 | E52: 70 | F52: 110 | G52: 360
B53: South | C53: 60 | D53: #N/A | E53: 140 | G53: #N/A
B54: Total | C54: 190 | D54: #N/A | E54: 210 | F54: 110 | G54: #N/A
A76: PIVOTBY(Data!A1:A13,Data!B1:B13,Data!C1:C13,SUM,2) | B76: {=_xlfn.PIVOTBY(Data!A1:A13,Data!B1:B13,Data!C1:C13,_xleta.SUM,2)} | C76: Column Field 1
C77: A | D77: B | E77: C | F77: Product | G77: 0 | H77: Total
B78: Row Field 1 | C78: Value 1 | D78: Value 1 | E78: Value 1 | F78: Value 1 | G78: Value 1 | H78: Value 1
B79: North | C79: 130 | D79: 50 | E79: 70 | G79: 110 | H79: 360
B80: Region | F80: 0 | H80: 0
B81: South | C81: 60 | D81: #N/A | E81: 140 | H81: #N/A
B82: Total | C82: 190 | D82: #N/A | E82: 210 | F82: 0 | G82: 110 | H82: #N/A
A101: PIVOTBY(Data!A1:A13,Data!B1:B13,Data!C1:C13,SUM,3) | B101: {=_xlfn.PIVOTBY(Data!A1:A13,Data!B1:B13,Data!C1:C13,_xleta.SUM,3)} | C101: Product
C102: A | D102: B | E102: C | F102: 0 | G102: Total
B103: Region | C103: Units | D103: Units | E103: Units | F103: Units | G103: Units
B104: North | C104: 130 | D104: 50 | E104: 70 | F104: 110 | G104: 360
B105: South | C105: 60 | D105: #N/A | E105: 140 | G105: #N/A
B106: Total | C106: 190 | D106: #N/A | E106: 210 | F106: 110 | G106: #N/A
A126: PIVOTBY(Data!A2:A13,Data!B2:B13,Data!D2:D13,SUM,0,0) | B126: {=_xlfn.PIVOTBY(Data!A2:A13,Data!B2:B13,Data!D2:D13,_xleta.SUM,0,0)} | C126: A | D126: B | E126: C | F126: 0 | G126: Total
B127: North | C127: 4.5 | D127: 2.25 | E127: 3 | F127: 1.5 | G127: 11.25
B128: South | C128: 1.5 | D128: 6.75 | E128: 6 | G128: 14.25
A151: PIVOTBY(Data!A2:A13,Data!B2:B13,Data!D2:D13,SUM,0,-1) | B151: {=_xlfn.PIVOTBY(Data!A2:A13,Data!B2:B13,Data!D2:D13,_xleta.SUM,0,-1)} | C151: A | D151: B | E151: C | F151: 0 | G151: Total
B152: Total | C152: 6 | D152: 9 | E152: 9 | F152: 1.5 | G152: 25.5
B153: North | C153: 4.5 | D153: 2.25 | E153: 3 | F153: 1.5 | G153: 11.25
B154: South | C154: 1.5 | D154: 6.75 | E154: 6 | G154: 14.25
A176: PIVOTBY(Data!A2:A13,Data!B2:B13,Data!D2:D13,SUM,0,2) | B176: {=_xlfn.PIVOTBY(Data!A2:A13,Data!B2:B13,Data!D2:D13,_xleta.SUM,0,2)} -> #VALUE!
A201: PIVOTBY(Data!A2:A13,Data!B2:B13,Data!D2:D13,SUM,0,1,,0) | B201: {=_xlfn.PIVOTBY(Data!A2:A13,Data!B2:B13,Data!D2:D13,_xleta.SUM,0,1,,0)} | C201: A | D201: B | E201: C | F201: 0
B202: North | C202: 4.5 | D202: 2.25 | E202: 3 | F202: 1.5
B203: South | C203: 1.5 | D203: 6.75 | E203: 6
B204: Total | C204: 6 | D204: 9 | E204: 9 | F204: 1.5
A226: PIVOTBY(Data!A2:A13,Data!B2:B13,Data!D2:D13,SUM,0,1,,-1) | B226: {=_xlfn.PIVOTBY(Data!A2:A13,Data!B2:B13,Data!D2:D13,_xleta.SUM,0,1,,-1)} | C226: Total | D226: A | E226: B | F226: C | G226: 0
B227: North | C227: 11.25 | D227: 4.5 | E227: 2.25 | F227: 3 | G227: 1.5
...

Sheet Pct
A1: PERCENTOF(Data!D2:D7,Data!D2:D13) | B1: {=_xlfn.PERCENTOF(Data!D2:D7,Data!D2:D13)} -> 0.47058824
A26: PERCENTOF(Data!C2:C13,Data!C2:C13) | B26: {=_xlfn.PERCENTOF(Data!C2:C13,Data!C2:C13)} -> #NUM!
A51: PERCENTOF(Data!B2:B4,Data!D2:D4) | B51: {=_xlfn.PERCENTOF(Data!B2:B4,Data!D2:D4)} -> 0
A76: PERCENTOF({1,2},{0,0}) | B76: {=_xlfn.PERCENTOF({1,2},{0,0})} -> #DIV/0!
A101: PERCENTOF(5,10) | B101: {=_xlfn.PERCENTOF(5,10)} -> 0.5
A126: PERCENTOF(Data!D2:D7,Data!C2:C11) | B126: {=_xlfn.PERCENTOF(Data!D2:D7,Data!C2:C11)} -> 0.021818182
